Workbook

Sheet Executive Dashboard
A1: ABTalks - Release by 20 September 2026
A2: Plan 112 rev.5. SUNDAYS ARE HOLIDAYS (6, 13, 20 Sep). 20 Sep IS a Sunday, so the product must be LIVE and VERIFIED on Saturday 19 September. Build 5-15 Sep (9 working days) · FREEZE Tue 15, 20:00 · UAT 16-18 · RELEASE Sat 19.
A4: THE COMPRESSED WEEK | I4: OPEN BUGS
A5: Milestone | B5: Date | C5: Working days away | I5: Severity | J5: Open | K5: Closed | L5: Total
A6: Today | B6: 46270 | C6: =NETWORKDAYS.INTL(TODAY(),$B6,11)-1 | I6: BLOCKER | J6: =COUNTIFS('Bugs'!$D$6:$D$205,$I6,'Bugs'!$G$6:$G$205,"Open")+COUNTIFS('Bugs'!$D$6:$D$205,$I6,'Bugs'!$G$6:$G$205,"In Fix")+COUNTIFS('Bugs'!$D$6:$D$205,$I6,'Bugs'!$G$6:$G$205,"Retest") | K6: =COUNTIFS('Bugs'!$D$6:$D$205,$I6,'Bugs'!$G$6:$G$205,"Closed") | L6: =COUNTIF('Bugs'!$D$6:$D$205,$I6)
A7: Foundation gate | B7: 46273 | C7: =NETWORKDAYS.INTL(TODAY(),$B7,11)-1 | I7: MAJOR | J7: =COUNTIFS('Bugs'!$D$6:$D$205,$I7,'Bugs'!$G$6:$G$205,"Open")+COUNTIFS('Bugs'!$D$6:$D$205,$I7,'Bugs'!$G$6:$G$205,"In Fix")+COUNTIFS('Bugs'!$D$6:$D$205,$I7,'Bugs'!$G$6:$G$205,"Retest") | K7: =COUNTIFS('Bugs'!$D$6:$D$205,$I7,'Bugs'!$G$6:$G$205,"Closed") | L7: =COUNTIF('Bugs'!$D$6:$D$205,$I7)
A8: Build wave 1 ends | B8: 46277 | C8: =NETWORKDAYS.INTL(TODAY(),$B8,11)-1 | I8: MINOR | J8: =COUNTIFS('Bugs'!$D$6:$D$205,$I8,'Bugs'!$G$6:$G$205,"Open")+COUNTIFS('Bugs'!$D$6:$D$205,$I8,'Bugs'!$G$6:$G$205,"In Fix")+COUNTIFS('Bugs'!$D$6:$D$205,$I8,'Bugs'!$G$6:$G$205,"Retest") | K8: =COUNTIFS('Bugs'!$D$6:$D$205,$I8,'Bugs'!$G$6:$G$205,"Closed") | L8: =COUNTIF('Bugs'!$D$6:$D$205,$I8)
A9: FEATURE FREEZE 20:00 | B9: 46280 | C9: =NETWORKDAYS.INTL(TODAY(),$B9,11)-1 | I9: COSMETIC | J9: =COUNTIFS('Bugs'!$D$6:$D$205,$I9,'Bugs'!$G$6:$G$205,"Open")+COUNTIFS('Bugs'!$D$6:$D$205,$I9,'Bugs'!$G$6:$G$205,"In Fix")+COUNTIFS('Bugs'!$D$6:$D$205,$I9,'Bugs'!$G$6:$G$205,"Retest") | K9: =COUNTIFS('Bugs'!$D$6:$D$205,$I9,'Bugs'!$G$6:$G$205,"Closed") | L9: =COUNTIF('Bugs'!$D$6:$D$205,$I9)
A10: UAT - find only | B10: 46281 | C10: =NETWORKDAYS.INTL(TODAY(),$B10,11)-1
A11: Fix blockers | B11: 46282 | C11: =NETWORKDAYS.INTL(TODAY(),$B11,11)-1 | I11: CAN WE SIGN OFF? | J11: =IF($J6+$J7>0,"NO - "&($J6+$J7)&" blocker/major open","YES - clear to sign off")
A12: Regression + sign-off | B12: 46283 | C12: =NETWORKDAYS.INTL(TODAY(),$B12,11)-1
A13: RELEASE + go live | B13: 46284 | C13: =NETWORKDAYS.INTL(TODAY(),$B13,11)-1
A14: Sun 20 Sep = DEADLINE DATE ONLY. Sundays 6, 13, 20 are holidays - nobody works them.
A16: P0 PROGRESS | I16: DESIGN PIPELINE - is design the bottleneck?
A17: P0 tasks | B17: =COUNTIF('Team Execution Board'!$E$2:$E$90,"P0") | I17: Designs NOT STARTED | J17: =COUNTIF('UI-UX'!$F$6:$F$15,"Not Started")
A18: P0 done | B18: =COUNTIFS('Team Execution Board'!$E$2:$E$90,"P0",'Team Execution Board'!$L$2:$L$90,"Done") | I18: Designs in progress | J18: =COUNTIF('UI-UX'!$F$6:$F$15,"In Design")
A19: P0 in progress | B19: =COUNTIFS('Team Execution Board'!$E$2:$E$90,"P0",'Team Execution Board'!$L$2:$L$90,"In Progress")+COUNTIFS('Team Execution Board'!$E$2:$E$90,"P0",'Team Execution Board'!$L$2:$L$90,"In Review") | I19: Designs approved | J19: =COUNTIF('UI-UX'!$F$6:$F$15,"Approved")
A20: P0 BLOCKED | B20: =COUNTIFS('Team Execution Board'!$E$2:$E$90,"P0",'Team Execution Board'!$L$2:$L$90,"Blocked") | I20: DEV WAITING ON DESIGN | J20: =COUNTIFS('Team Execution Board'!$K$2:$K$90,"Not Started",'Team Execution Board'!$L$2:$L$90,"<>Done")+COUNTIFS('Team Execution Board'!$K$2:$K$90,"In Design",'Team Execution Board'!$L$2:$L$90,"<>Done")
A21: P0 not started | B21: =COUNTIFS('Team Execution Board'!$E$2:$E$90,"P0",'Team Execution Board'!$L$2:$L$90,"Not Started") | I21: Features awaiting UI/UX QA | J21: =COUNTIF('Team Execution Board'!$M$2:$M$90,"Pending")+COUNTIF('Team Execution Board'!$M$2:$M$90,"In QA")
A22: P0 % complete | B22: =IFERROR($B18/$B17,0) | I22: UI/UX NEEDS FIX | J22: =COUNTIF('Team Execution Board'!$M$2:$M$90,"NEEDS FIX")
A23: P0 days of work | B23: =SUMIF('Team Execution Board'!$E$2:$E$90,"P0",'Team Execution Board'!$P$2:$P$90)
A24: HIGH RISK P0 not done | B24: =COUNTIFS('Team Execution Board'!$E$2:$E$90,"P0",'Team Execution Board'!$F$2:$F$90,"HIGH",'Team Execution Board'!$L$2:$L$90,"<>Done") | I24: SCOPE
A25: OVERDUE | B25: =SUMPRODUCT(('Team Execution Board'!$O$2:$O$90<TODAY())*('Team Execution Board'!$L$2:$L$90<>"Done")*('Team Execution Board'!$L$2:$L$90<>"Deferred")*('Team Execution Board'!$E$2:$E$90="P0")) | I25: P0 - MUST ship by Sat 19 Sep | J25: =COUNTIF('Team Execution Board'!$E$2:$E$90,"P0")&" tasks / "&ROUND(SUMIF('Team Execution Board'!$E$2:$E$90,"P0",'Team Execution Board'!$P$2:$P$90),1)&" days"
I26: P1 - only if P0 lands early | J26: =COUNTIF('Team Execution Board'!$E$2:$E$90,"P1")&" tasks / "&ROUND(SUMIF('Team Execution Board'!$E$2:$E$90,"P1",'Team Execution Board'!$P$2:$P$90),1)&" days"
I27: P2 - October | J27: =COUNTIF('Team Execution Board'!$E$2:$E$90,"P2")&" tasks / "&ROUND(SUMIF('Team Execution Board'!$E$2:$E$90,"P2",'Team Execution Board'!$P$2:$P$90),1)&" days"
A29: BY PERSON | I29: WHERE TO LOOK
A30: Person | B30: Role | C30: Tasks | D30: Done | E30: Blocked | F30: Days | G30: % done | I30: Developers | J30: Team Execution Board - filter to your name
A31: Shivansh | B31: Developer - full time | C31: =COUNTIF('Team Execution Board'!$G$2:$G$90,$A31) | D31: =COUNTIFS('Team Execution Board'!$G$2:$G$90,$A31,'Team Execution Board'!$L$2:$L$90,"Done") | E31: =COUNTIFS('Team Execution Board'!$G$2:$G$90,$A31,'Team Execution Board'!$L$2:$L$90,"Blocked") | F31: =SUMIF('Team Execution Board'!$G$2:$G$90,$A31,'Team Execution Board'!$P$2:$P$90) | G31: =IFERROR($D31/$C31,0) | I31: Shallika | J31: UI-UX sheet, then Team Execution Board Design Status
A32: Zainab | B32: Developer - full time | C32: =COUNTIF('Team Execution Board'!$G$2:$G$90,$A32) | D32: =COUNTIFS('Team Execution Board'!$G$2:$G$90,$A32,'Team Execution Board'!$L$2:$L$90,"Done") | E32: =COUNTIFS('Team Execution Board'!$G$2:$G$90,$A32,'Team Execution Board'!$L$2:$L$90,"Blocked") | F32: =SUMIF('Team Execution Board'!$G$2:$G$90,$A32,'Team Execution Board'!$P$2:$P$90) | G32: =IFERROR($D32/$C32,0) | I32: First time | J32: How We Work - read it once
A33: shashank | B33: Developer - full time | C33: =COUNTIF('Team Execution Board'!$G$2:$G$90,$A33) | D33: =COUNTIFS('Team Execution Board'!$G$2:$G$90,$A33,'Team Execution Board'!$L$2:$L$90,"Done") | E33: =COUNTIFS('Team Execution Board'!$G$2:$G$90,$A33,'Team Execution Board'!$L$2:$L$90,"Blocked") | F33: =SUMIF('Team Execution Board'!$G$2:$G$90,$A33,'Team Execution Board'!$P$2:$P$90) | G33: =IFERROR($D33/$C33,0) | I33: Prompts | J33: AI Prompt Library - P1 first, P13 for designs
A34: Manuvrtti | B34: Developer - part time | C34: =COUNTIF('Team Execution Board'!$G$2:$G$90,$A34) | D34: =COUNTIFS('Team Execution Board'!$G$2:$G$90,$A34,'Team Execution Board'!$L$2:$L$90,"Done") | E34: =COUNTIFS('Team Execution Board'!$G$2:$G$90,$A34,'Team Execution Board'!$L$2:$L$90,"Blocked") | F34: =SUMIF('Team Execution Board'!$G$2:$G$90,$A34,'Team Execution Board'!$P$2:$P$90) | G34: =IFERROR($D34/$C34,0) | I34: What we promised | J34: User Journeys
A35: Sohail | B35: Architect + builder | C35: =COUNTIF('Team Execution Board'!$G$2:$G$90,$A35) | D35: =COUNTIFS('Team Execution Board'!$G$2:$G$90,$A35,'Team Execution Board'!$L$2:$L$90,"Done") | E35: =COUNTIFS('Team Execution Board'!$G$2:$G$90,$A35,'Team Execution Board'!$L$2:$L$90,"Blocked") | F35: =SUMIF('Team Execution Board'!$G$2:$G$90,$A35,'Team Execution Board'!$P$2:$P$90) | G35: =IFERROR($D35/$C35,0) | I35: Testing | J35: E2E Tests · UAT · Bugs
A36: Shallika | B36: UI/UX Designer - full time, no code | C36: =COUNTIF('Team Execution Board'!$G$2:$G$90,$A36) | D36: =COUNTIFS('Team Execution Board'!$G$2:$G$90,$A36,'Team Execution Board'!$L$2:$L$90,"Done") | E36: =COUNTIFS('Team Execution Board'!$G$2:$G$90,$A36,'Team Execution Board'!$L$2:$L$90,"Blocked") | F36: =SUMIF('Team Execution Board'!$G$2:$G$90,$A36,'Team Execution Board'!$P$2:$P$90) | G36: =IFERROR($D36/$C36,0) | I36: Release day | J36: Milestones & Release

Sheet Delivery Risk
A1: Delivery Risk - the capacity gap, stated honestly
A2: The full committed product is in this workbook. Nothing has been deferred. This sheet exists because the arithmetic does not close, and hiding that would be worse than saying it.
A4: THE ARITHMETIC
A5: Working days remaining (5 - 19 Sep, Sundays off) | B5: 13 | D5: Sundays 6, 13 and 20 September are holidays.
A6: Of which build days (5, 7-12, 14-16) | B6: 10 | D6: 17-18 are UAT and fixes; 19 is release day. Testing is continuous inside each task, not a phase.
A7: Full-time developers | B7: 3 | D7: Shivansh, Zainab, shashank.
A8: Part-time developer | B8: 0.4 FTE | D8: Manuvrtti.
A9: Architect who also builds | B9: 0.6 FTE | D9: Sohail - the rest of his time is review, decisions and release.
A10: Designer | B10: 1.0 FTE | D10: Shallika - design capacity, NOT development capacity.
A11: GROSS developer capacity | B11: 40.0 days | D11: 10 build days x 4.0 developer FTE.
A12: EFFECTIVE capacity after review, deploy and the unexpected | B12: 34.0 days | D12: 15% deducted, which is optimistic for a junior team on a large existing codebase.
A13: COMMITTED SCOPE after every simplification | B13: 60.4 days | D13: Already reduced by 11.6 days through reuse and simpler implementations - see below.
A14: THE GAP | B14: 26.4 days | D14: This is the number. It cannot be closed by scheduling.
A15: 26.4 developer-days short over 10 build days = the work of roughly 2.6 additional full-time developers. Parallelisation cannot recover it: the existing team is already scheduled at 150-200% of capacity, so there is no idle time to redirect.
A18: WHAT HAS ALREADY BEEN DONE TO CLOSE IT - 11.6 days recovered, no functionality removed
A19: Workstream | B19: Was | C19: Now | D19: How - same user outcome, less machinery
A20: Jobs & applicants | B20: 6.5d | C20: 5.0d | D20: Job-skill storage already exists unused. Simple pagination rather than keyset.
A21: Evidence layer | B21: 5.0d | C21: 3.5d | D21: Emitter plus the four highest-value sources. Backfill becomes a release-day operation, not build work.
A22: Assessments | B22: 4.0d | C22: 3.5d | D22: Question storage AND result storage both already exist unused. Multiple-choice only.
A23: Candidate insights | B23: 3.0d | C23: 2.0d | D23: Existing scoring and match-explanation code reused. Deterministic facts and gaps, no scoring engine.
A24: Non-technical hiring | B24: 3.0d | C24: 1.5d | D24: Taxonomy extension and skill seed only - search already filters on skills.
A25: Recruiter notifications | B25: 2.8d | C25: 1.5d | D25: Configuration over the shared notification helper, not new infrastructure.
A26: Recruiter analytics | B26: 2.5d | C26: 1.5d | D26: Plain counts over tables other workstreams already write. No reporting layer.
A27: Product analytics | B27: 2.4d | C27: 1.0d | D27: One table, one helper. Each feature owner adds their own events inside their own task.
A28: Mock interview | B28: 2.0d | C28: 1.5d | D28: Audit and blocker fixes only. The interview engine is not extended.
A29: Cohorts & hackathons | B29: 2.0d | C29: 1.5d | D29: Audit and blocker fixes only. Infrastructure is not rebuilt.
A30: Profile-view tracking | B30: 1.5d | C30: 1.0d | D30: One table, one write path, one count.
A31: External profile links | B31: 1.4d | C31: 1.0d | D31: Link storage already exists. Declared links only - nothing is fetched.
A33: THE OPTIONS - A, B, C and E are already applied and are inside the 11.6 days above
A34: Option | B34: Recovers | C34: Verdict | D34: Detail
A35: A - more parallel ownership | B35: ~0 days | C35: Already exhausted | D35: Every developer is scheduled at or above 100%. There is no idle capacity to redirect. Parallelisation prevents waste; it does not create hours.
A36: B - simpler implementation | B36: 11.6 days | C36: APPLIED | D36: Listed above. Going further starts removing acceptance criteria rather than machinery - which is removing the product by another name.
A37: C - reuse existing code | B37: included in B | C37: APPLIED | D37: Roughly 8 of the 11.6 days come from unused schema that already exists: talent lists, candidate notes, job skills, question storage and assessment results.
A38: D - add engineering capacity | B38: 26.4 days | C38: THE ONLY OPTION THAT CLOSES THE GAP | D38: About 2.6 additional full-time developers for the whole window, productive from Monday 7 September. Allow for onboarding: on a codebase this size, a new developer is unlikely to be net-positive before day three, so 3 developers is the safer number.
A39: E - cut non-functional polish | B39: ~2 days | C39: APPLIED | D39: Animation, decorative polish and platform-wide visual consistency are already out. The design consistency pass is scoped to the September journeys only.
A41: IF NO CAPACITY IS ADDED: the plan does not fit, and the honest consequence is that some committed functionality will be incomplete on 19 September. That decision belongs to the product lead, not to the schedule - and it must be taken deliberately at the Saturday 12 September gate, not discovered on the 18th. The execution order in this workbook (P0 then P1 then P2) is exactly the order in which work should land, so that whatever is unfinished is the least critical, not the most recent.

Sheet Requirements Coverage
A1: Requirements Coverage - every committed requirement, checked
A2: One row per requirement from the committed product scope. DELIVERED IN PLAN must read YES for every one. A NO would mean something was silently dropped - there are none.
A3: ="72 committed requirements | DELIVERED IN PLAN: "&COUNTIF($G$6:$G$77,"YES")&" | NOT DELIVERED: "&COUNTIF($G$6:$G$77,"NO")
A5: # | B5: Side | C5: Requirement | D5: Where it is delivered | E5: Owner | F5: Priority (execution order) | G5: Delivered in plan
A6: 1 | B6: Candidate | C6: register | D6: C1 Candidate Profile & Discoverability | E6: Shivansh | F6: P0 | G6: YES
A7: 2 | B7: Candidate | C7: complete onboarding | D7: C1 Candidate Profile & Discoverability | E7: Shivansh | F7: P0 | G7: YES
A8: 3 | B8: Candidate | C8: create / edit profile | D8: C1 Candidate Profile & Discoverability | E8: Shivansh | F8: P0 | G8: YES
A9: 4 | B9: Candidate | C9: upload resume | D9: C1 Candidate Profile & Discoverability | E9: Shivansh | F9: P0 | G9: YES
A10: 5 | B10: Candidate | C10: add education | D10: C1 Candidate Profile & Discoverability | E10: Shivansh | F10: P0 | G10: YES
A11: 6 | B11: Candidate | C11: add experience | D11: C1 Candidate Profile & Discoverability | E11: Shivansh | F11: P0 | G11: YES
A12: 7 | B12: Candidate | C12: add internships | D12: C1 Candidate Profile & Discoverability | E12: Shivansh | F12: P0 | G12: YES
A13: 8 | B13: Candidate | C13: add projects | D13: C1 Candidate Profile & Discoverability | E13: Shivansh | F13: P0 | G13: YES
A14: 9 | B14: Candidate | C14: add certifications | D14: C1 Candidate Profile & Discoverability | E14: Shivansh | F14: P0 | G14: YES
A15: 10 | B15: Candidate | C15: add achievements | D15: C1 Candidate Profile & Discoverability | E15: Shivansh | F15: P0 | G15: YES
A16: 11 | B16: Candidate | C16: add skills | D16: C1 Candidate Profile & Discoverability | E16: Shivansh | F16: P0 | G16: YES
A17: 12 | B17: Candidate | C17: add job preferences | D17: C1 Candidate Profile & Discoverability | E17: Shivansh | F17: P0 | G17: YES
... A77: 72 | B77: Design | C77: UI/UX QA on the running application | D77: D0 Design Foundation & System | E77: Shallika | F77: P0 | G77: YES
A79: Priority here is EXECUTION ORDER, not a deferral list. P0 is critical-path and built first; P1 follows once its dependencies exist; P2 is lower-critical-path work that still belongs to the September commitment. Nothing on this sheet has been moved to October. See 'Delivery Risk' for the capacity gap that threatens the last of it.

Sheet Team Execution Board
A1: Task ID | B1: Workstream | C1: Journey step | D1: User outcome - what must be true when this is done | E1: Priority | F1: Risk | G1: Feature Owner | H1: Design Owner | I1: Development Owner | J1: Technical Reviewer | K1: Design Status | L1: Dev Status | M1: UI/UX QA | N1: Start | O1: Deadline | P1: Days | Q1: Current state check - find this out FIRST | R1: What needs to work | S1: Design dependency | T1: AI prompts | U1: Manual test - in a real browser | V1: Automated test expectation | W1: Acceptance criteria | X1: Regression check - what you did NOT build | Y1: Evidence required | Z1: Depends on | AA1: Decision | AB1: Blocker / notes
A2: T-001 | B2: G0 Decisions & Foundations | C2: Decisions that unblock everyone | D2: As the team, we need the decisions that block everyone settled before Wednesday. | E2: P0 | F2: HIGH | G2: Sohail | H2: - | I2: Sohail | J2: Sohail owns and signs this himself. | K2: Not Required | L2: Not Started | M2: Not Required | N2: 46270 | O2: 46273 | P2: 1.2 | Q2: Three are already agreed (payments deferred, contact unlock by plan allowance, no company verification) - just record them. The rest need a call. | R2: Every blocking decision is written down with a one-line reason. Nobody builds against a guess. | S2: - | T2: No AI. Product judgement. | U2: Open the decision record. Every question has an answer, not a question. | V2: None - written artefact. | W2: All decisions marked Decided with a reason and the tasks each unblocks. No task starts Wednesday against an open decision. | X2: None. | Y2: The committed decision record. | Z2: - | AA2: -
A3: T-002 | B3: G0 Decisions & Foundations | C3: Decisions that unblock everyone | D3: As the team, we must know that database changes can reach production before we write any. | E3: P0 | F3: HIGH | G3: Sohail | H3: - | I3: Sohail | J3: Sohail owns and signs this himself. | K3: Not Required | L3: Not Started | M3: Not Required | N3: 46270 | O3: 46270 | P3: 0.4 | Q3: The docs contradict each other. Settle it with a real run against a COPY of the database, never production. | R3: Either the path is proven on a copy of the database, or the blocker is understood and resolved. Written down either way. | S3: - | T3: P11 Database review. Ask Claude to explain the blocker, not fix it. | U3: Run it against a copy. Read the output. Paste it into the decision record. | V3: None. | W3: Output recorded. If it failed, the resolution is written down and tested. No database change merges until this is done. | X3: None - a copy cannot affect production. | Y3: Claude investigation plan (before code) + Sohail's written approval + test output + preview URL + the created record id + PR link. | Z3: - | AA3: D-2
A4: T-003 | B4: G0 Decisions & Foundations | C4: Decisions that unblock everyone | D4: As a developer, I need the shared helpers to exist so I am not blocked by someone else's feature. | E4: P0 | F4: MEDIUM | G4: Zainab | H4: - | I4: Zainab | J4: Sohail writes these himself - they are contracts. | K4: Not Required | L4: Not Started | M4: Not Required | N4: 46272 | O4: 46273 | P4: 0.5 | Q4: None exist. Check for anything similar before creating new files. | R4: Four shared helpers exist as no-op stubs that type-check: check a plan limit, send a notification, record a candidate signal, add someone to a shortlist. | S4: - | T4: P1 Investigate -> P2 Plan -> P3 Implement | U4: Import each from a test file. The project builds. | V4: One trivial test per stub. | W4: All four on the main branch by Tuesday evening so every consumer can keep moving. | X4: None - no-op stubs. | Y4: Screen recording of the manual test + test output + PR link + Claude summary. | Z4: - | AA4: -
A5: T-004 | B5: G0 Decisions & Foundations | C5: Decisions that unblock everyone | D5: As the project lead, I need to know on Tuesday evening whether we can safely start building. | E5: P0 | F5: MEDIUM | G5: Sohail | H5: - | I5: Sohail | J5: Sohail owns and signs this himself. | K5: Not Required | L5: Not Started | M5: Not Required | N5: 46273 | O5: 46273 | P5: 0.2 | Q5: Check: decisions closed, stubs merged, database path proven, designs approved for wave 1. | R5: A go/no-go call, written down. | S5: - | T5: None. | U5: Read the four criteria. Sign or don't. | V5: None. | W5: Signed. If the database path is unproven, no database change merges Wednesday - we re-sequence instead. | X5: None. | Y5: Signed gate row. | Z5: - | AA5: -
A6: T-005 | B6: D0 Design Foundation & System | C6: How the product should feel | D6: As the team, we need to know where the product currently looks and feels inconsistent - but only on the journeys we are shipping. | E6: P0 | F6: LOW | G6: Shallika | H6: Shallika | I6: - | J6: Sohail reviews to confirm scope has not crept beyond September journeys. | K6: In Design | L6: Not Started | M6: Not Required | N6: 46270 | O6: 46272 | P6: 1 | Q6: Walk the live product as a real recruiter and a real candidate. Note what confuses you. Stay inside the September journeys - do not audit pages we are not shipping. | R6: A short written audit of the recruiter and candidate journeys in the 20 Sep scope: inconsistent buttons, forms, cards, spacing, typography, navigation, missing states, confusing steps, responsive breakages. NOT a whole-platform review. | S6: - | T6: No AI needed. | U6: Walk both journeys end to end. Screenshot every inconsistency. | V6: None. | W6: A written list, grouped by journey, ranked by how much it hurts the user. Anything not on a September journey is marked P2 and parked. | X6: None - no code. | Y6: The audit document with screenshots. | Z6: - | AA6: -
A7: T-006 | B7: D0 Design Foundation & System | C7: How the product should feel | D7: As a developer, I need agreed patterns so I am not inventing a button style at 11pm. | E7: P0 | F7: LOW | G7: Shallika | H7: Shallika | I7: - | J7: Sohail confirms it builds on the existing design system rather than replacing it. | K7: In Design | L7: Not Started | M7: Not Required | N7: 46272 | O7: 46273 | P7: 1 | Q7: A design system document already exists in the repo. EXTEND it - do not start a new one, and do not redesign components that already work. | R7: The handful of patterns these journeys need are defined and named: buttons, inputs, dropdowns, cards, tables, badges, modals, navigation, alerts/toasts, plus loading, empty, error and success states. | S7: - | T7: No AI needed. | U7: A developer can point at any element in the September journeys and find its pattern. | V7: None. | W7: Patterns documented and referenced from the design files. Small enough to be usable this month - this is consistency, not an enterprise system. | X7: None. | Y7: The pattern reference, linked from every design. | Z7: - | AA7: -
A8: T-007 | B8: D0 Design Foundation & System | C8: How the product should feel | D8: As a recruiter, signing up and landing in my workspace should feel like a real product. | E8: P0 | F8: LOW | G8: Shallika | H8: Shallika | I8: - | J8: Sohail reviews against the recruiter journey before it is marked Approved. | K8: In Design | L8: Not Started | M8: Not Required | N8: 46270 | O8: 46273 | P8: 1.8 | Q8: Read the recruiter journey on the User Journeys sheet first. Design the FLOW, not five separate screens. | R8: Approved designs for recruiter signup, the five onboarding steps, the workspace shell and Home - including every state and how they behave on a phone. | S8: - | T8: No AI needed. | U8: Walk a developer through the flow. They can describe what happens at every step without asking you a question. | V8: None. | W8: Every screen and every state: loading, empty, error, success, disabled. Desktop and mobile. Handoff includes the user goal, the flow, what each component does, validation behaviour and interaction notes. APPROVED before Wednesday so R1 and R12 can start. | X8: None. | Y8: Design link + states covered + Sohail's approval. | Z8: - | AA8: -
A9: T-008 | B9: D0 Design Foundation & System | C9: How the product should feel | D9: As a recruiter, finding and choosing candidates should feel considered, not like a database query. | E9: P0 | F9: LOW | G9: Shallika | H9: Shallika | I9: - | J9: Sohail reviews against the recruiter journey before Approved. | K9: In Design | L9: Not Started | M9: Not Required | N9: 46274 | O9: 46276 | P9: 1.8 | Q9: This is the heart of the product. Think through the whole journey: enter project, set criteria, search, understand a candidate card, shortlist, come back next week and still understand where you were. | R9: Approved designs for the talent project, the criteria panel, search results, the candidate card, the shortlist and the pipeline board - designed as ONE connected flow. | S9: - | T9: No AI needed. | U9: Walk the flow with Sohail and shashank. It makes sense without explanation. | V9: None. | W9: Complete flow with all states, including what a recruiter sees with zero results and with a brand-new empty project. Approved before the search build starts on the 11th. | X9: None. | Y9: Design link + states + approval. | Z9: - | AA9: -
A10: T-009 | B10: D0 Design Foundation & System | C10: How the product should feel | D10: As a candidate, building my profile should feel quick and worth doing. | E10: P0 | F10: LOW | G10: Shallika | H10: Shallika | I10: - | J10: Sohail reviews against the candidate journey before Approved. | K10: In Design | L10: Not Started | M10: Not Required | N10: 46276 | O10: 46277 | P10: 1.2 | Q10: Key product rule: a candidate does NOT need verified evidence to be discoverable. Self-declared skills must feel legitimate, while staying visibly different from verified ones. | R10: Approved designs for candidate signup, the profile sections, adding self-declared skills, and the privacy/visibility control - including what a recruiter sees. | S10: - | T10: No AI needed. | U10: Walk it with Shivansh. The difference between self-declared and verified is obvious without a legend. | V10: None. | W10: All sections and states. Self-declared and verified are visually distinct and honestly labelled. Mobile covered. Approved before the profile build finishes. | X10: None. | Y10: Design link + states + approval. | Z10: - | AA10: -
A11: T-010 | B11: D0 Design Foundation & System | C11: How the product should feel | D11: As a recruiter, unlocking and contacting a candidate should feel deliberate and clear. | E11: P0 | F11: LOW | G11: Shallika | H11: Shallika | I11: - | J11: Sohail reviews before Approved. | K11: In Design | L11: Not Started | M11: Not Required | N11: 46277 | O11: 46279 | P11: 1 | Q11: This is where money meets privacy. The recruiter must understand what they are spending and the candidate must be treated respectfully. | R11: Approved designs for the contact unlock, the allowance indicator, the message composer and the outreach history - including what a recruiter with no allowance left sees. | S11: - | T11: No AI needed. | U11: Walk it with Zainab. What happens at zero allowance is obvious. | V11: None. | W11: Unlock, spend, compose, send, history, and the zero-allowance state all designed. Approved before the outreach build starts. | X11: None. | Y11: Design link + states + approval. | Z11: - | AA11: -
A12: T-011 | B12: D0 Design Foundation & System | C12: How the product should feel | D12: As the designer, I need to check what was actually built, not what was designed. | E12: P0 | F12: LOW | G12: Shallika | H12: Shallika | I12: - | J12: Shallika signs; Sohail arbitrates if a blocker is disputed. | K12: Not Required | L12: Not Started | M12: In QA | N12: 46279 | O12: 46280 | P12: 1.2 | Q12: Open the preview and use it. Compare against the approved design. | R12: Every feature from build wave 1 is reviewed in the running application - not from screenshots. | S12: - | T12: No AI needed. | U12: For each wave-1 feature check: does it match the design, does it work on a phone, hover and focus states, loading, errors, empty states, spacing, typography, consistency, and anything confusing. | V12: None. | W12: Every wave-1 feature has a recorded UI/UX SIGN-OFF of PASS or NEEDS FIX. Issues are ranked BLOCKER / MAJOR / MINOR. Minor cosmetic issues become P2 bugs - they do NOT block the release. | X12: None. | Y12: Sign-off record per feature with ranked issues. | Z12: - | AA12: -
A13: T-012 | B13: D0 Design Foundation & System | C13: How the product should feel | D13: As the designer, I need to check the whole product one final time before we ship. | E13: P0 | F13: LOW | G13: Shallika | H13: Shallika | I13: - | J13: Shallika signs. A disputed blocker goes to Sohail. | K13: Not Required | L13: Not Started | M13: In QA | N13: 46281 | O13: 46282 | P13: 1.5 | Q13: This is the last chance to catch something that makes the product feel unfinished. | R13: Every September journey reviewed end to end in the running application on desktop and mobile. | S13: - | T13: None. | U13: Walk the recruiter journey and the candidate journey end to end, on a laptop and on a phone. Log every issue with a rank. | V13: None. | W13: Both journeys signed off. Blockers fixed before release; majors fixed if time allows; minors logged for October. A minor cosmetic issue never blocks the release. | X13: None. | Y13: Final UI/UX sign-off for both journeys. | Z13: - | AA13: -
... A90: T-089 | B90: C5 Cohorts & Hackathons | C90: Learning signal | D90: As a new candidate, I can join a cohort or a hackathon and have it count. | E90: P2 | F90: MEDIUM | G90: Zainab | H90: - | I90: Zainab | J90: Peer review (Shivansh<->shashank, Zainab<->Manuvrtti) + prompt P7 before merge. | K90: Not Required | L90: Not Started | M90: Not Required | N90: 46281 | O90: 46281 | P90: 1.5 | Q90: Live for months but never proven for a NEW user. Walk both as a real user FIRST. Record what duplicate submission actually does rather than assuming. Do not rebuild the infrastructure. | R90: Both journeys are walked on production with fresh accounts, every blocking break is fixed, and completing work records proof a recruiter can see. | S90: - | T90: P1 Investigate -> P2 Plan -> P3 Implement | U90: Fresh account: find a cohort, enrol, complete an activity, submit, see it marked. Fresh participant: find a hackathon, register alone AND in a team, submit, try a duplicate, see the result. Then check a recruiter can see the resulting signal. | V90: A test that completing an activity records proof. | W90: Both journeys complete for a genuinely new user. Proof recorded and visible to a recruiter - 'the record was written' is not enough, the recruiter view is checked. | X90: MANDATORY: complete one existing challenge task - points and progress still work. | Y90: Screen recording of the manual test + test output + PR link + Claude summary. | Z90: P1 | AA90: -

Sheet UI-UX
A1: UI/UX - Shallika
A2: Design runs AHEAD of development. A feature is not ready for a developer until its design is Approved, and it is not Done until Shallika has reviewed it in the running application. Small cosmetic issues become October bugs - they never block the release.
A3: ="Designs approved: "&COUNTIF($F$6:$F$15,"Approved")&" of 9 P0 | In design: "&COUNTIF($F$6:$F$15,"In Design")&" | NOT STARTED: "&COUNTIF($F$6:$F$15,"Not Started")
A5: Design ID | B5: Feature / journey | C5: Priority | D5: Design start | E5: Design deadline | F5: Status | G5: Screens required | H5: States required | I5: Responsive | J5: Dev depends on it? | K5: Developer | L5: UI/UX QA | M5: Issues found | N5: Sign-off
A6: UX-1 | B6: Design audit of the September journeys only | C6: P0 | D6: 46270 | E6: 46272 | F6: In Design | G6: n/a - written audit | H6: n/a | I6: n/a | J6: No | K6: - | L6: Not Required
A7: UX-2 | B7: Shared patterns: buttons, inputs, cards, tables, badges, modals, nav, alerts | C7: P0 | D7: 46272 | E7: 46273 | F7: In Design | G7: Pattern reference | H7: Loading · empty · error · success · disabled | I7: Desktop + mobile | J7: Yes - all frontend | K7: All | L7: Not Required
A8: UX-3 | B8: Recruiter signup, 5-step onboarding, workspace shell, Home | C8: P0 | D8: 46270 | E8: 46273 | F8: In Design | G8: Signup · OTP · company · hiring need · plan · Home · shell | H8: All 5 states + resume-from-interruption | I8: Desktop + mobile | J8: Yes - blocks R1, R12 | K8: Shivansh | L8: Pending
A9: UX-4 | B9: Talent project, criteria panel, search results, candidate card, shortlist, pipeline board | C9: P0 | D9: 46274 | E9: 46276 | F9: Not Started | G9: Project list · project detail · criteria · results · card · board | H9: All 5 states + zero results + brand-new empty project | I9: Desktop + mobile | J9: Yes - blocks R3, R5 | K9: shashank | L9: Pending
A10: UX-5 | B10: Candidate signup, profile sections, self-declared skills, privacy control | C10: P0 | D10: 46276 | E10: 46277 | F10: Not Started | G10: Signup · profile · skills · privacy · recruiter preview | H10: All 5 states; self-declared vs verified visibly distinct | I10: Desktop + mobile | J10: Yes - blocks C1 | K10: Shivansh | L10: Pending
A11: UX-6 | B11: Contact unlock, allowance indicator, message composer, outreach history | C11: P0 | D11: 46277 | E11: 46279 | F11: Not Started | G11: Unlock · composer · history | H11: All 5 states + the zero-allowance state | I11: Desktop + mobile | J11: Yes - blocks R6 | K11: Zainab | L11: Pending
A12: UX-7 | B12: Notification bell and preferences | C12: P0 | D12: 46277 | E12: 46279 | F12: Not Started | G12: Bell · list · preferences | H12: Empty · unread · read | I12: Desktop + mobile | J12: Yes - blocks P2 | K12: Manuvrtti | L12: Pending
A13: UX-8 | B13: UI/UX QA of build wave 1 in the running app | C13: P0 | D13: 46279 | E13: 46280 | F13: Not Started | G13: n/a - review | H13: Verify every state was actually built | I13: Check both | J13: No | K13: All | L13: In QA
A14: UX-9 | B14: Final UI/UX pass, both journeys, desktop and mobile | C14: P0 | D14: 46281 | E14: 46283 | F14: Not Started | G14: n/a - review | H14: Full journey walk-through | I14: Both | J14: No | K14: All | L14: In QA
A15: UX-10 | B15: Platform-wide visual consistency beyond September journeys | C15: P2 | D15: - | E15: - | F15: Deferred | G15: - | H15: - | I15: - | J15: No | K15: - | L15: Not Required | M15: MOVED TO OCTOBER - a full redesign is not attempted before 20 Sep.

Sheet How We Work
A1: How We Work Every Day
A2: Read this once, properly. It is the difference between AI helping you ship and AI quietly breaking production. ABTalks is a large live platform with real users - almost every task below CHANGES something that already exists.
A5: THE ONE RULE
B6: Investigate → Plan → Review → Implement → Test → Manual check → Regression → Done | C6: Never: prompt → generate a lot of code → hope it works. ABTalks already has 964 source files and real users. The most expensive mistake on this project is asking AI to build something that already exists, or to replace something that is working.
B7: Why this matters here | C7: Roughly a third of the recruiter product already exists in the database and is simply unused. If you ask Claude to 'build a shortlist' it will happily build a second one. If you ask it 'what already stores a shortlist and why is it not being used', you get a two-hour task instead of a two-day one.
A9: YOUR DAY, STEP BY STEP
B10: 1. Read your row | C10: Read the User Outcome and the Acceptance Criteria on the Team Execution Board. If you cannot picture the finished thing in your head, ask at standup BEFORE starting.
B11: 2. Ask Claude to investigate - NO CODE | C11: Paste prompt P1 from the AI Prompt Library. Let it read the relevant part of the codebase and tell you what already exists. Do not let it write anything yet.
B12: 3. Ask for a plan | C12: Paste P2. Read the plan yourself. If any step surprises you, ask why before agreeing.
B13: 4. Check the assumptions | C13: If Claude writes 'I assume...' anywhere - go and verify it. An unchecked assumption is the most common cause of a broken feature.
B14: 5. HIGH RISK? Stop here | C14: If your row says HIGH, send the plan to Sohail and wait. Do not start coding. This is not a formality - these are the tasks that can lose data or leak candidate details.
B15: 6. Implement one piece at a time | C15: Paste P3. One logical change, then check it works, then the next. Never ten changes and one big test.
B16: 7. Run the existing tests | C16: Before yours. If something unrelated breaks, STOP - you have changed something you did not mean to.
B17: 8. Add tests | C17: Ask Claude to follow the project's existing testing approach. You do not need to know that approach in advance - Claude should find it.
B18: 9. Do the manual test | C18: The steps in your row. In a real browser. As a real user would. This catches what tests do not.
B19: 10. Do the regression check | C19: The Regression Check column. This is testing what you did NOT build - the things your change could have broken.
B20: 11. Ask Claude to review its own work | C20: Paste P7, ideally in a fresh conversation so it reviews with clean eyes. Fix the blockers and majors.
B21: 12. Mark it done | C21: Only when every acceptance checkbox is true AND you have the evidence listed in your row.
A23: STOP → ASK SOHAIL
B24: Stop immediately and ask, whatever Claude says | C24: Claude proposes deleting production data · a change that rewrites or drops existing records · changing how login or permissions work · replacing an existing subsystem · a database change whose result differs from what was expected · row counts that do not reconcile · tests failing in an area you did not touch · Claude cannot explain how the existing code works · the requirement contradicts what production actually does · anything about who can see candidate contact details · a change that needs a large unrelated refactor to work · anything that changes production settings · Claude making assumptions about live data. You will never be criticised for stopping. You will be asked hard questions if you did not.
A26: RULES FOR EVERY AI PROMPT
B27: Do not scan the whole repository | C27: Start from the page or route for your feature. Follow its direct dependencies. Widen only when you must. This keeps Claude accurate and cheap.
B28: No unrelated refactoring | C28: Do not rename unrelated files. Do not replace working code because another approach looks cleaner. Do not add a library when the current stack can do it. We are optimising for shipping, not architectural beauty.
B29: No parallel implementations | C29: If something already does 80% of this, extend it. A second way of doing the same thing is how this codebase ends up with two shortlists - which is exactly the bug we are fixing this month.
B30: Smallest safe change | C30: Preserve existing behaviour unless the requirement explicitly changes it.
B31: Report everything | C31: Every file changed, every assumption made, and anything it could not verify.
A33: THE WEEK - Sunday is a HOLIDAY
B34: Working days | C34: Mon-Sat. SUNDAY IS OFF for everyone: 6, 13 and 20 September. No development, design, QA, review, testing or meetings are scheduled on a Sunday.
B35: The deadline | C35: 20 September is itself a SUNDAY. So the product must be LIVE and VERIFIED on Saturday 19 September. The 20th is the stated deadline date only - nobody works it.
B36: What that leaves | C36: 13 working days from 5 September, of which only NINE are build days. Everything after Tuesday 15 September is freeze, testing, fixing and release.
A38: DESIGN COMES FIRST - and runs AHEAD
B39: The pipeline | C39: DESIGN READY -> READY FOR DEVELOPMENT -> IN DEVELOPMENT -> FUNCTIONALLY READY -> UI/UX QA -> UAT -> DONE.
B40: Shallika works a feature ahead | C40: While you build feature A, she is designing feature B. Never wait for a design that should already exist - if your row says a design is required and it is not Approved, raise it at standup THAT MORNING.
B41: Check before you start | C41: If your row has a Design dependency, confirm the design is Approved on the UI-UX sheet before writing frontend code. Building against an unapproved design means building it twice.
B42: Backend work does not wait | C42: Database, authorization, plan limits, migrations and pure data tasks proceed independently. Do not invent a design dependency where there is no meaningful UI.
B43: Do not redesign it yourself | C43: The approved design is authoritative. If it is technically impossible or conflicts with existing behaviour, REPORT the conflict - do not quietly change it.
B44: UI/UX QA is a real gate | C44: Shallika reviews the running application, not screenshots. She records PASS or NEEDS FIX. Blockers must be fixed. Minor cosmetic issues become October bugs and never block the release.
A46: RISK LEVELS - what your row means
B47: LOW | C47: Screens, states, forms, copy, responsive work, filtering with existing data. Build it with Claude, self-review with P7, normal pull request.
B48: MEDIUM | C48: New user flows, search behaviour, notifications, emails, analytics, anything that persists. Investigation → plan → build → tests → manual journey → peer review before merge.
...

Sheet AI Prompt Library
A1: Claude / Cursor Prompt Library
A2: Copy the prompt, replace the [SQUARE BRACKETS], paste it in. Your Team Execution Board row tells you which prompts to use and in what order. Always start with P1 - never with P3.
A4: Ref | B4: Use it when | C4: The prompt - copy from here
A5: P1 | B5: Investigate - ALWAYS FIRST. Never skip this. | C5: You are working on ABTalks, a large live Next.js + Prisma platform with real users. IMPORTANT SCOPE RULES: - Do not scan or modify the whole repository. Start from the page/route/module for this feature and follow its direct dependencies. Widen context only when necessary. - Prefer extending existing code over creating anything new. - Do not refactor unrelated code, rename unrelated files, or introduce a new library. TASK: [PASTE THE USER OUTCOME AND ACCEPTANCE CRITERIA FROM YOUR ROW] DO NOT WRITE ANY CODE YET. Inspect only the parts of the repository relevant to this feature and tell me: 1. The current user flow - what actually happens today, step by step. 2. The frontend components involved. 3. The backend actions or endpoints involved. 4. The database models involved, and whether any of them already exist but are UNUSED. 5. How authentication and permissions currently work on this path. 6. What tests already exist for this area. 7. Patterns already used elsewhere in this codebase that I should reuse rather than reinvent. Then tell me plainly: - What already works. - What is half-built. - What is missing. - What could BREAK if we change this. - The specific files you believe need changing, and why each one. If you are unsure about something, say so explicitly rather than guessing.
A6: P2 | B6: Get a plan before any code | C6: Based on your investigation, write an implementation plan. Rules: - Reuse existing models, components and utilities wherever possible. Tell me exactly what you are reusing. - If you are creating anything new, justify why nothing existing can be extended. - Break the work into small, individually testable steps. - For each step, say what could break and how we would notice. - List every file you will touch. - State every assumption you are making, clearly marked, so I can verify it. - Flag anything that touches login, permissions, candidate contact details, existing data, or database structure. Do not implement anything yet. I will review this plan first.
A7: P3 | B7: Implement an approved plan | C7: Implement the approved plan step by step. Rules: - Make the smallest safe change. - Preserve existing behaviour unless the requirement explicitly changes it. - Reuse existing utilities, components and services. - Do not create a second implementation of something that already exists. - Do not refactor unrelated code. Do not rename unrelated files. - Add or update tests using this project's existing testing approach. - Run the relevant existing tests after implementing. After each logical step, stop and report: - Every file you changed and why. - Every assumption you made. - Anything you could not verify. - Any existing behaviour you think may be affected.
A8: P4 | B8: Something is broken and you need the cause | C8: You are working on ABTalks, a large live Next.js + Prisma platform with real users. IMPORTANT SCOPE RULES: - Do not scan or modify the whole repository. Start from the page/route/module for this feature and follow its direct dependencies. Widen context only when necessary. - Prefer extending existing code over creating anything new. - Do not refactor unrelated code, rename unrelated files, or introduce a new library. BUG: [DESCRIBE WHAT YOU DID AND WHAT HAPPENED INSTEAD] Do not fix anything yet. Trace the actual code path this request takes. Tell me: 1. Where the behaviour diverges from what I expected. 2. The root cause, not the symptom. 3. Whether this is a new bug or pre-existing. 4. What else uses this same code path and could be affected by a fix. 5. The smallest fix that addresses the root cause. If you cannot reproduce the cause from the code, say so - do not guess.
A9: P5 | B9: Before merging anything that touches shared systems | C9: I am about to change [DESCRIBE THE CHANGE]. Acting as a cautious reviewer, tell me: 1. Every existing user flow that touches this code. 2. Which of those could break, and how a user would notice. 3. Anything relying on the current behaviour that I might not have thought of. 4. The specific manual tests I should run on the EXISTING functionality after this change. Be specific. 'Test the profile' is not useful - tell me which screen, which action, which expected result.
A10: P6 | B10: Add tests for what you just built | C10: Add tests for [FEATURE]. First, inspect how tests are already written in this repository and follow that same approach - do not introduce a new framework or pattern. Cover: - The main path working correctly. - The failure the acceptance criteria call out. - Permissions: someone who should NOT be able to do this, cannot. - Data persisting correctly across a fresh read. Then run them and show me the output.
A11: P7 | B11: Review your own work - ideally in a FRESH chat | C11: Review this implementation as a senior engineer who did not write it. Do not change anything yet. Look for: - Requirement gaps - Broken existing behaviour - Incorrect assumptions - Security problems - Permission and data-isolation issues - Data consistency issues - Unnecessary complexity - Duplicated logic - Missing error states - Missing tests - Unhandled edge cases Rank every issue as BLOCKER, MAJOR or MINOR. Then recommend the smallest fix for each.
A12: P8 | B12: Write or repair an automated journey test | C12: Write an automated end-to-end test for this journey: [PASTE THE SCENARIO AND STEPS FROM THE E2E TESTS SHEET] First inspect how end-to-end tests are already set up in this repository and use that same framework and structure. The test must: - Start from a genuinely fresh account, not a reused one. - Follow the steps exactly as written. - Assert the specific expected result, not just that the page loaded. - Fail loudly and readably when the journey breaks. Show me the test and how to run it.
A13: P9 | B13: Check how a screen looks and behaves | C13: Review this screen against the project's design system document. Do not change anything yet. Check: - Does it reuse existing patterns and tokens, or invent new ones? - Loading, empty, error and success states - are all four present and designed? - Does it work at phone width without sideways scrolling or cut-off buttons? - Are tap targets big enough? - Is anything inconsistent with the neighbouring screens? List issues as BLOCKER, MAJOR or MINOR and suggest the smallest fixes.
A14: P10 | B14: Anything touching permissions or personal data | C14: Security review this change. Do not change anything yet. Check specifically: 1. Is the restriction enforced on the SERVER, or only in the browser? Show me the server-side check. 2. Can this be bypassed by calling the action directly, without the UI? 3. Can a user from one company reach another company's data by changing an id? 4. Does any response contain personal data - email, phone, CV link - that the caller should not see? Check the actual response payload, not the rendered screen. 5. Are public pages such as sign-in and sign-out still public? For each, tell me how you verified it, and rank problems as BLOCKER, MAJOR or MINOR.
A15: P11 | B15: Anything changing the database or moving data | C15: Review this database change. Do not run anything against production. Tell me: 1. Exactly what will change and whether any existing row is rewritten or removed. 2. Whether existing records keep working afterwards - be specific about defaults and nullability. 3. What happens to data currently in these tables. 4. Whether this can be undone, and how. 5. How we verify afterwards that nothing was lost - the exact counts or checks to run before and after. 6. Whether this needs to run in batches to avoid timing out. This must be rehearsed on a Neon CHILD branch first. Never target the production branch.
... A18: P12 | B18: Before you say a feature is done | C18: Assess whether this feature is genuinely production-ready. Be sceptical - assume it is not. Check: - Does the whole user journey work, or only the screen? - Does the data survive a sign-out and sign-in? - Are permissions enforced on the server? - Do loading, empty, error and success states exist? - Does it work on a phone? - Are there tests, and do they test the real behaviour rather than the implementation? - What happens on a slow connection, a failed request, or a duplicate submission? - What existing functionality could this have broken, and has that been tested? Give me a straight answer: ready, or not ready and why.

Sheet User Journeys
A1: User Journeys - the committed September product
A2: EVERY row here ships. Priority is EXECUTION ORDER, not a deferral list: P0 is critical-path and built first, P1 follows once its dependencies exist, P2 is lower-critical-path work still inside the September commitment. The release is declared on Saturday 19 September only when every row is verified on the live site by its owner.
A3: ="Verified live: "&COUNTIF($H$6:$H$39,"VERIFIED LIVE")&" of 34 committed journey steps | EVERY row ships - the release is declared only at 34 of 34"
A5: # | B5: Persona | C5: Step | D5: What the person can do | E5: Priority | F5: Feature owner | G5: Designer | H5: Verified live?
A6: 1 | B6: Candidate | C6: Sign up | D6: Register quickly and reach a dashboard that says what to do next. | E6: P0 | F6: Shivansh | G6: Shallika | H6: Not Started
A7: 2 | B7: Candidate | C7: Build a profile | D7: Resume, education, experience, internships, projects, certifications, achievements, preferences - all persist. | E7: P0 | F7: Shivansh | G7: Shallika | H7: Not Started
A8: 3 | B8: Candidate | C8: Declare my skills | D8: Say what I am good at WITHOUT needing ABTalks to verify it first. | E8: P0 | F8: Shivansh | G8: Shallika | H8: Not Started
A9: 4 | B9: Candidate | C9: Be discoverable | D9: Appear in recruiter search on my self-declared skills, honestly labelled. | E9: P0 | F9: Shivansh | G9: Shallika | H9: Not Started
A10: 5 | B10: Candidate | C10: Control my privacy | D10: Decide what recruiters see and check it myself before trusting it. | E10: P0 | F10: Shivansh | G10: Shallika | H10: Not Started
A11: 6 | B11: Candidate | C11: Browse and apply for jobs | D11: Search and filter jobs, apply once, and track what happened. | E11: P1 | F11: Shivansh | G11: Shallika | H11: Not Started
A12: 7 | B12: Candidate | C12: Have my work count as proof | D12: Verified activity becomes evidence that strengthens recruiter confidence. | E12: P1 | F12: Zainab | G12: - | H12: Not Started
A13: 8 | B13: Candidate | C13: Take a recruiter's test | D13: Receive a test, take it without losing my answers, and see my result. | E13: P1 | F13: Zainab | G13: Shallika | H13: Not Started
A14: 9 | B14: Candidate | C14: Practise interviewing | D14: Finish a mock interview and get a report that counts. | E14: P2 | F14: Zainab | G14: Shallika | H14: Not Started
A15: 10 | B15: Candidate | C15: Join cohorts and hackathons | D15: Enrol, take part, finish, and have it count. | E15: P2 | F15: Zainab | G15: - | H15: Not Started
A16: 11 | B16: Candidate | C16: Add my external profiles | D16: GitHub, LeetCode and CodeChef, honestly labelled as self-reported. | E16: P2 | F16: Manuvrtti | G16: Shallika | H16: Not Started
A17: 12 | B17: Candidate | C17: Know who viewed me | D17: See that real recruiters are looking at my profile. | E17: P2 | F17: shashank | G17: Shallika | H17: Not Started
... A39: 34 | B39: Platform | C39: Safe to release | D39: Journeys tested, regression checked, verified on the live site. | E39: P0 | F39: Sohail | G39: - | H39: Not Started

Sheet E2E Tests
A1: Automated Journey Tests
A2: Six journeys for the compressed release. Prompt P8 tells Claude to inspect how tests are already written here and follow that - you do not need to know the framework first, but you DO need to walk the journey by hand.
A5: ID | B5: Journey | C5: Persona | D5: Owner | E5: You need first | F5: Steps | G5: Expected result | H5: Status
A6: E2E-1 | B6: Recruiter signs up, onboards and reaches the workspace | C6: Recruiter | D6: Shivansh | E6: A fresh invited email | F6: Register · verify by code · company details · hiring need · plan · admin activates · land on Home. Repeat, closing the browser at the company step. | G6: Every step saves. Closing halfway and returning resumes at the right step. Lands on Home, not search. Limits live after activation. | H6: Not Written
A7: E2E-2 | B7: Candidate signs up, declares skills and becomes findable | C7: Candidate | D7: Shivansh | E7: A fresh candidate account | F7: Register · complete the profile · add three self-declared skills · set visibility · have a recruiter search that skill. | G7: The candidate appears in search on SELF-DECLARED skills alone, marked as self-declared and never as verified. Turning visibility off removes them from live search AND saved lists. | H7: Not Written
A8: E2E-3 | B8: Recruiter creates a project, leaves and comes back | C8: Recruiter | D8: shashank | E8: A recruiter with a plan and candidates | F8: Create a named project · set criteria · search · view one · shortlist one · reject one · sign out · sign in IN A DIFFERENT BROWSER · reopen · re-run the search. | G8: Criteria and all three candidate states exactly as left. Only genuinely new candidates are marked new. | H8: Not Written
A9: E2E-4 | B9: Recruiter unlocks a candidate and emails them | C9: Recruiter | D9: Zainab | E9: A recruiter with contact allowance | F9: Search · open a candidate · shortlist · unlock contact · write and send an email · check the pipeline and history. | G9: Unlock reduces the allowance by one. The email sends. The candidate moves to contacted. A recruiter with NO allowance gets no contact details anywhere in the response. | H9: Not Written
A10: E2E-5 | B10: Plan limits cannot be bypassed | C10: Recruiter | D10: Sohail | E10: A recruiter at their limit | F10: For each restricted action: use it up through the screen, then call the action directly with the browser bypassed. Then fire ten simultaneous requests against a limit of five. | G10: Every one refused by the server. Exactly five of the ten succeed. Refusals are readable messages, not errors. | H10: Not Written
A11: E2E-6 | B11: Nobody sees what they should not | C11: Recruiter | D11: Sohail | E11: Two separate companies | F11: As company A, request company B's project, shortlist, note and candidate records by id. As a candidate, open recruiter and admin screens. Check responses for a non-unlocked candidate. | G11: All refused by the server. No candidate email, phone or CV link in any response for a candidate who has not been unlocked. | H11: Not Written

Sheet UAT
A1: UAT - anyone can run these
A2: Wed 16 - Fri 18 September. Always a BRAND NEW account, never your own. Nobody tests their own work. On Wednesday you only FIND problems; you do not fix them.
A5: ID | B5: What we are checking | C5: Who runs it | D5: Whose fix | E5: Steps | F5: What should happen | G5: If it fails | H5: Wed 16 | I5: Fri 18
A6: UAT-1 | B6: Recruiter onboarding survives an interruption | C6: Zainab | D6: Shivansh | E6: 1. Create a fresh recruiter account. 2. Enter your company details. 3. CLOSE THE BROWSER halfway. 4. Reopen the site and log in. 5. Continue and finish. | F6: Everything you typed is still there and you carry on where you stopped. You never start again. You end on a home page that tells you what to do next. | G6: BLOCKER | H6: Not Run | I6: Not Run
A7: UAT-2 | B7: A recruiter understands what their plan allows | C7: Zainab | D7: Sohail | E7: 1. Look at the plans page. 2. Note how many searches you get. 3. Use them up. 4. Try one more. 5. Check your usage figures. | F7: You can see what you get before committing. When you run out you are told clearly what ran out and where to upgrade - not shown an error. | G7: BLOCKER | H7: Not Run | I7: Not Run
A8: UAT-3 | B8: A hiring project remembers everything | C8: Shivansh | D8: shashank | E8: 1. Create a project called 'Frontend Developer'. 2. Add the skills and experience you want. 3. Search. 4. Shortlist three people. 5. Reject one. 6. Log out. 7. Log in FROM A DIFFERENT BROWSER. 8. Open the project. | F8: The project, your criteria, your three shortlisted people and your one rejection are all exactly as you left them. | G8: BLOCKER | H8: Not Run | I8: Not Run
A9: UAT-4 | B9: Contacting a candidate works | C9: Shivansh | D9: Zainab | E9: 1. Shortlist someone. 2. Unlock their contact details. 3. Check your remaining allowance. 4. Write and send them an email. 5. CHECK THE CANDIDATE'S REAL INBOX. 6. Look at their status. | F9: You see their details, your allowance drops by one, a real email arrives within a minute, and the candidate is now marked contacted. | G9: BLOCKER | H9: Not Run | I9: Not Run
A10: UAT-5 | B10: A recruiter with no allowance cannot see contact details | C10: Shivansh | D10: Zainab | E10: 1. Use up all your contact unlocks. 2. Open a candidate. 3. Try to unlock. 4. Try to email them. | F10: You are told you have run out. You cannot see their email or phone anywhere. You cannot message them. | G10: BLOCKER | H10: Not Run | I10: Not Run
A11: UAT-6 | B11: Notifications arrive and stop when switched off | C11: Manuvrtti | D11: Manuvrtti | E11: 1. Trigger the notifications these journeys produce. 2. Check the bell. 3. Check a real inbox. 4. Switch one off and repeat. | F11: You are told about the things that matter. Each notification takes you to the right place. Switching one off actually stops it. | G11: BLOCKER | H11: Not Run | I11: Not Run
A12: UAT-7 | B12: The product feels like ONE product | C12: Manuvrtti | D12: Shivansh | E12: 1. Sit someone who has NEVER seen ABTalks in front of a recruiter account. 2. Ask them to find a candidate, save them and message them. 3. SAY NOTHING. 4. Write down every pause or question. | F12: They get there on their own. Every hesitation is worth fixing - write each one down. | G12: MAJOR | H12: Not Run | I12: Not Run
A13: UAT-8 | B13: A candidate profile keeps everything | C13: shashank | D13: Shivansh | E13: 1. Fill in every part of your profile. 2. Save. 3. Log out and back in. 4. Change four things. 5. Delete one thing from three sections. 6. Look at the recruiter preview. | F13: Nothing is lost. Changes stuck. Everything deleted is gone, including from the recruiter view. | G13: BLOCKER | H13: Not Run | I13: Not Run
A14: UAT-9 | B14: A candidate is findable on skills they typed themselves | C14: shashank | D14: Shivansh | E14: 1. As a fresh candidate, add three skills yourself - do not complete any ABTalks activity. 2. As a recruiter, search for one of those skills. 3. Open the candidate. | F14: The candidate appears in search purely on what they typed. The recruiter can clearly see those skills are self-declared, not verified by ABTalks. | G14: BLOCKER | H14: Not Run | I14: Not Run
